<robot name="panda">
  <link name="panda_link0">
  	<inertial>
      <origin rpy="0 0 0" xyz="0 0 0.05" />
       <mass value="2.9" />
       <inertia ixx="0.1" ixy="0" ixz="0" iyy="0.1" iyz="0" izz="0.1" />
    </inertial>
    <visual>
      <geometry>
        <mesh filename="hd_meshes/visual/link0.dae" />
      </geometry>
      <material name="panda_white">
    		<color rgba="1. 1. 1. 1." />
  		</material>
    </visual>
    <collision>
      <geometry>
        <mesh filename="hd_meshes/collision/link0.vhacd.00.obj" />
      </geometry>
      <material name="panda_white" />
    </collision>
  <collision>
      <geometry>
        <mesh filename="hd_meshes/collision/link0.vhacd.01.obj" />
      </geometry>
      <material name="panda_white" />
    </collision>
  <collision>
      <geometry>
        <mesh filename="hd_meshes/collision/link0.vhacd.02.obj" />
      </geometry>
      <material name="panda_white" />
    </collision>
  <collision>
      <geometry>
        <mesh filename="hd_meshes/collision/link0.vhacd.03.obj" />
      </geometry>
      <material name="panda_white" />
    </collision>
  </link>
  <link name="panda_link1">
  	<inertial>
      <origin rpy="0 0 0" xyz="0 -0.04 -0.05" />
       <mass value="2.7" />
       <inertia ixx="0.1" ixy="0" ixz="0" iyy="0.1" iyz="0" izz="0.1" />
    </inertial>
    <visual>
      <geometry>
        <mesh filename="hd_meshes/visual/link1.dae" />
      </geometry>
      <material name="panda_white" />
    </visual>
    <collision>
      <geometry>
        <mesh filename="hd_meshes/collision/link1.vhacd.00.obj" />
      </geometry>
      <material name="panda_white" />
    </collision>
  <collision>
      <geometry>
        <mesh filename="hd_meshes/collision/link1.vhacd.01.obj" />
      </geometry>
      <material name="panda_white" />
    </collision>
  </link>
  <joint name="panda_joint1" type="revolute">
    <safety_controller k_position="100.0" k_velocity="40.0" soft_lower_limit="-2.8973" soft_upper_limit="2.8973" />
    <origin rpy="0 0 0" xyz="0 0 0.333" />
    <parent link="panda_link0" />
    <child link="panda_link1" />
    <axis xyz="0 0 1" />
    <limit effort="87" lower="-2.8973" upper="2.8973" velocity="2.1750" />
  </joint>
  <link name="panda_link2">
  	<inertial>
      <origin rpy="0 0 0" xyz="0 -0.04 0.06" />
       <mass value="2.73" />
       <inertia ixx="0.1" ixy="0" ixz="0" iyy="0.1" iyz="0" izz="0.1" />
    </inertial>
    <visual>
      <geometry>
        <mesh filename="hd_meshes/visual/link2.dae" />
      </geometry>
      <material name="panda_white" />
    </visual>
    <collision>
      <geometry>
        <mesh filename="hd_meshes/collision/link2.vhacd.00.obj" />
      </geometry>
      <material name="panda_white" />
    </collision>
  <collision>
      <geometry>
        <mesh filename="hd_meshes/collision/link2.vhacd.01.obj" />
      </geometry>
      <material name="panda_white" />
    </collision>
  <collision>
      <geometry>
        <mesh filename="hd_meshes/collision/link2.vhacd.02.obj" />
      </geometry>
      <material name="panda_white" />
    </collision>
  </link>
  <joint name="panda_joint2" type="revolute">
    <safety_controller k_position="100.0" k_velocity="40.0" soft_lower_limit="-1.7628" soft_upper_limit="1.7628" />
    <origin rpy="-1.57079632679 0 0" xyz="0 0 0" />
    <parent link="panda_link1" />
    <child link="panda_link2" />
    <axis xyz="0 0 1" />
    <limit effort="87" lower="-1.7628" upper="1.7628" velocity="2.1750" />
  </joint>
  <link name="panda_link3">
	  <inertial>
      <origin rpy="0 0 0" xyz="0.01 0.01 -0.05" />
       <mass value="2.04" />
       <inertia ixx="0.1" ixy="0" ixz="0" iyy="0.1" iyz="0" izz="0.1" />
    </inertial>
    <visual>
      <geometry>
        <mesh filename="hd_meshes/visual/link3.dae" />
      </geometry>
      <material name="panda_red">
    		<color rgba="1. 1. 1. 1." />
  		</material>
    </visual>
    <collision>
      <geometry>
        <mesh filename="hd_meshes/collision/link3.vhacd.00.obj" />
      </geometry>
    </collision>
  <collision>
      <geometry>
        <mesh filename="hd_meshes/collision/link3.vhacd.01.obj" />
      </geometry>
    </collision>
  <collision>
      <geometry>
        <mesh filename="hd_meshes/collision/link3.vhacd.02.obj" />
      </geometry>
    </collision>
  <collision>
      <geometry>
        <mesh filename="hd_meshes/collision/link3.vhacd.03.obj" />
      </geometry>
    </collision>
  </link>
  <joint name="panda_joint3" type="revolute">
    <safety_controller k_position="100.0" k_velocity="40.0" soft_lower_limit="-2.8973" soft_upper_limit="2.8973" />
    <origin rpy="1.57079632679 0 0" xyz="0 -0.316 0" />
    <parent link="panda_link2" />
    <child link="panda_link3" />
    <axis xyz="0 0 1" />
    <limit effort="87" lower="-2.8973" upper="2.8973" velocity="2.1750" />
  </joint>
  <link name="panda_link4">
  	<inertial>
      <origin rpy="0 0 0" xyz="-0.03 0.03 0.02" />
       <mass value="2.08" />
       <inertia ixx="0.1" ixy="0" ixz="0" iyy="0.1" iyz="0" izz="0.1" />
    </inertial>
    <visual>
      <geometry>
        <mesh filename="hd_meshes/visual/link4.dae" />
      </geometry>
      <material name="panda_white" />
    </visual>
    <collision>
      <geometry>
        <mesh filename="hd_meshes/collision/link4.vhacd.00.obj" />
      </geometry>
      <material name="panda_white" />
    </collision>
  <collision>
      <geometry>
        <mesh filename="hd_meshes/collision/link4.vhacd.01.obj" />
      </geometry>
      <material name="panda_white" />
    </collision>
  <collision>
      <geometry>
        <mesh filename="hd_meshes/collision/link4.vhacd.02.obj" />
      </geometry>
      <material name="panda_white" />
    </collision>
  <collision>
      <geometry>
        <mesh filename="hd_meshes/collision/link4.vhacd.03.obj" />
      </geometry>
      <material name="panda_white" />
    </collision>
  </link>
  <joint name="panda_joint4" type="revolute">
    <safety_controller k_position="100.0" k_velocity="40.0" soft_lower_limit="-3.0718" soft_upper_limit="-0.0698" />
    <origin rpy="1.57079632679 0 0" xyz="0.0825 0 0" />
    <parent link="panda_link3" />
    <child link="panda_link4" />
    <axis xyz="0 0 1" />
    <limit effort="87" lower="-3.0718" upper="-0.0698" velocity="2.1750" />
  </joint>
  <link name="panda_link5">
  	<inertial>
      <origin rpy="0 0 0" xyz="0 0.04 -0.12" />
       <mass value="3" />
       <inertia ixx="0.1" ixy="0" ixz="0" iyy="0.1" iyz="0" izz="0.1" />
    </inertial>
    <visual>
      <geometry>
        <mesh filename="hd_meshes/visual/link5.dae" />
      </geometry>
      <material name="panda_white" />
    </visual>
    <collision>
      <geometry>
        <mesh filename="hd_meshes/collision/link5.vhacd.00.obj" />
      </geometry>
      <material name="panda_white" />
    </collision>
  <collision>
      <geometry>
        <mesh filename="hd_meshes/collision/link5.vhacd.01.obj" />
      </geometry>
      <material name="panda_white" />
    </collision>
  <collision>
      <geometry>
        <mesh filename="hd_meshes/collision/link5.vhacd.02.obj" />
      </geometry>
      <material name="panda_white" />
    </collision>
  <collision>
      <geometry>
        <mesh filename="hd_meshes/collision/link5.vhacd.03.obj" />
      </geometry>
      <material name="panda_white" />
    </collision>
  </link>
  <joint name="panda_joint5" type="revolute">
    <safety_controller k_position="100.0" k_velocity="40.0" soft_lower_limit="-2.8973" soft_upper_limit="2.8973" />
    <origin rpy="-1.57079632679 0 0" xyz="-0.0825 0.384 0" />
    <parent link="panda_link4" />
    <child link="panda_link5" />
    <axis xyz="0 0 1" />
    <limit effort="12" lower="-2.8973" upper="2.8973" velocity="2.6100" />
  </joint>
  <link name="panda_link6">
  	<inertial>
      <origin rpy="0 0 0" xyz="0.04 0 0" />
       <mass value="1.3" />
       <inertia ixx="0.1" ixy="0" ixz="0" iyy="0.1" iyz="0" izz="0.1" />
    </inertial>
    <visual>
      <geometry>
        <mesh filename="hd_meshes/visual/link6.dae" />
      </geometry>
      <material name="panda_white" />
    </visual>
    <collision>
      <geometry>
        <mesh filename="hd_meshes/collision/link6.vhacd.00.obj" />
      </geometry>
      <material name="panda_white" />
    </collision>
  <collision>
      <geometry>
        <mesh filename="hd_meshes/collision/link6.vhacd.01.obj" />
      </geometry>
      <material name="panda_white" />
    </collision>
  <collision>
      <geometry>
        <mesh filename="hd_meshes/collision/link6.vhacd.02.obj" />
      </geometry>
      <material name="panda_white" />
    </collision>
  <collision>
      <geometry>
        <mesh filename="hd_meshes/collision/link6.vhacd.03.obj" />
      </geometry>
      <material name="panda_white" />
    </collision>
  <collision>
      <geometry>
        <mesh filename="hd_meshes/collision/link6.vhacd.04.obj" />
      </geometry>
      <material name="panda_white" />
    </collision>
  <collision>
      <geometry>
        <mesh filename="hd_meshes/collision/link6.vhacd.05.obj" />
      </geometry>
      <material name="panda_white" />
    </collision>
  <collision>
      <geometry>
        <mesh filename="hd_meshes/collision/link6.vhacd.06.obj" />
      </geometry>
      <material name="panda_white" />
    </collision>
  <collision>
      <geometry>
        <mesh filename="hd_meshes/collision/link6.vhacd.07.obj" />
      </geometry>
      <material name="panda_white" />
    </collision>
  <collision>
      <geometry>
        <mesh filename="hd_meshes/collision/link6.vhacd.08.obj" />
      </geometry>
      <material name="panda_white" />
    </collision>
  <collision>
      <geometry>
        <mesh filename="hd_meshes/collision/link6.vhacd.09.obj" />
      </geometry>
      <material name="panda_white" />
    </collision>
  <collision>
      <geometry>
        <mesh filename="hd_meshes/collision/link6.vhacd.10.obj" />
      </geometry>
      <material name="panda_white" />
    </collision>
  <collision>
      <geometry>
        <mesh filename="hd_meshes/collision/link6.vhacd.11.obj" />
      </geometry>
      <material name="panda_white" />
    </collision>
  <collision>
      <geometry>
        <mesh filename="hd_meshes/collision/link6.vhacd.12.obj" />
      </geometry>
      <material name="panda_white" />
    </collision>
  <collision>
      <geometry>
        <mesh filename="hd_meshes/collision/link6.vhacd.13.obj" />
      </geometry>
      <material name="panda_white" />
    </collision>
  <collision>
      <geometry>
        <mesh filename="hd_meshes/collision/link6.vhacd.14.obj" />
      </geometry>
      <material name="panda_white" />
    </collision>
  <collision>
      <geometry>
        <mesh filename="hd_meshes/collision/link6.vhacd.15.obj" />
      </geometry>
      <material name="panda_white" />
    </collision>
  <collision>
      <geometry>
        <mesh filename="hd_meshes/collision/link6.vhacd.16.obj" />
      </geometry>
      <material name="panda_white" />
    </collision>
  <collision>
      <geometry>
        <mesh filename="hd_meshes/collision/link6.vhacd.17.obj" />
      </geometry>
      <material name="panda_white" />
    </collision>
  <collision>
      <geometry>
        <mesh filename="hd_meshes/collision/link6.vhacd.18.obj" />
      </geometry>
      <material name="panda_white" />
    </collision>
  <collision>
      <geometry>
        <mesh filename="hd_meshes/collision/link6.vhacd.19.obj" />
      </geometry>
      <material name="panda_white" />
    </collision>
  <collision>
      <geometry>
        <mesh filename="hd_meshes/collision/link6.vhacd.20.obj" />
      </geometry>
      <material name="panda_white" />
    </collision>
  <collision>
      <geometry>
        <mesh filename="hd_meshes/collision/link6.vhacd.21.obj" />
      </geometry>
      <material name="panda_white" />
    </collision>
  <collision>
      <geometry>
        <mesh filename="hd_meshes/collision/link6.vhacd.22.obj" />
      </geometry>
      <material name="panda_white" />
    </collision>
  <collision>
      <geometry>
        <mesh filename="hd_meshes/collision/link6.vhacd.23.obj" />
      </geometry>
      <material name="panda_white" />
    </collision>
  <collision>
      <geometry>
        <mesh filename="hd_meshes/collision/link6.vhacd.24.obj" />
      </geometry>
      <material name="panda_white" />
    </collision>
  </link>
  <joint name="panda_joint6" type="revolute">
    <safety_controller k_position="100.0" k_velocity="40.0" soft_lower_limit="-0.0175" soft_upper_limit="3.7525" />
    <origin rpy="1.57079632679 0 0" xyz="0 0 0" />
    <parent link="panda_link5" />
    <child link="panda_link6" />
    <axis xyz="0 0 1" />
    <limit effort="12" lower="-0.0175" upper="3.7525" velocity="2.6100" />
  </joint>
  <link name="panda_link7">
  	<inertial>
      <origin rpy="0 0 0" xyz="0 0 0.08" />
       <mass value=".2" />
       <inertia ixx="0.1" ixy="0" ixz="0" iyy="0.1" iyz="0" izz="0.1" />
    </inertial>
    <visual>
      <geometry>
        <mesh filename="hd_meshes/visual/link7.dae" />
      </geometry>
      <material name="panda_white" />
    </visual>
    <collision>
      <geometry>
        <mesh filename="hd_meshes/collision/link7.vhacd.00.obj" />
      </geometry>
      <material name="panda_white" />
    </collision>
  <collision>
      <geometry>
        <mesh filename="hd_meshes/collision/link7.vhacd.01.obj" />
      </geometry>
      <material name="panda_white" />
    </collision>
  <collision>
      <geometry>
        <mesh filename="hd_meshes/collision/link7.vhacd.02.obj" />
      </geometry>
      <material name="panda_white" />
    </collision>
  <collision>
      <geometry>
        <mesh filename="hd_meshes/collision/link7.vhacd.03.obj" />
      </geometry>
      <material name="panda_white" />
    </collision>
  <collision>
      <geometry>
        <mesh filename="hd_meshes/collision/link7.vhacd.04.obj" />
      </geometry>
      <material name="panda_white" />
    </collision>
  <collision>
      <geometry>
        <mesh filename="hd_meshes/collision/link7.vhacd.05.obj" />
      </geometry>
      <material name="panda_white" />
    </collision>
  <collision>
      <geometry>
        <mesh filename="hd_meshes/collision/link7.vhacd.06.obj" />
      </geometry>
      <material name="panda_white" />
    </collision>
  <collision>
      <geometry>
        <mesh filename="hd_meshes/collision/link7.vhacd.07.obj" />
      </geometry>
      <material name="panda_white" />
    </collision>
  <collision>
      <geometry>
        <mesh filename="hd_meshes/collision/link7.vhacd.08.obj" />
      </geometry>
      <material name="panda_white" />
    </collision>
  <collision>
      <geometry>
        <mesh filename="hd_meshes/collision/link7.vhacd.09.obj" />
      </geometry>
      <material name="panda_white" />
    </collision>
  <collision>
      <geometry>
        <mesh filename="hd_meshes/collision/link7.vhacd.10.obj" />
      </geometry>
      <material name="panda_white" />
    </collision>
  </link>
  <joint name="panda_joint7" type="revolute">
    <safety_controller k_position="100.0" k_velocity="40.0" soft_lower_limit="-2.8973" soft_upper_limit="2.8973" />
    <origin rpy="1.57079632679 0 0" xyz="0.088 0 0" />
    <parent link="panda_link6" />
    <child link="panda_link7" />
    <axis xyz="0 0 1" />
    <limit effort="12" lower="-2.8973" upper="2.8973" velocity="2.6100" />
  </joint>
  <link name="panda_link8">
  	 <inertial>
      <origin rpy="0 0 0" xyz="0 0 0" />
       <mass value="0.0" />
       <inertia ixx="0.1" ixy="0" ixz="0" iyy="0.1" iyz="0" izz="0.1" />
    </inertial>
  </link>
  <joint name="panda_joint8" type="fixed">
    <origin rpy="0 0 0" xyz="0 0 0.107" />
    <parent link="panda_link7" />
    <child link="panda_link8" />
    <axis xyz="0 0 0" />
  </joint>
  <joint name="panda_hand_joint" type="fixed">
    <parent link="panda_link8" />
    <child link="panda_hand" />
    <origin rpy="0 0 -0.785398163397" xyz="0 0 0" />
  </joint>
  <link name="panda_hand">
  	<inertial>
      <origin rpy="0 0 0" xyz="0 0 0.04" />
       <mass value=".81" />
       <inertia ixx="0.1" ixy="0" ixz="0" iyy="0.1" iyz="0" izz="0.1" />
    </inertial>
    <visual>
      <geometry>
        <mesh filename="hd_meshes/visual/hand.dae" />
      </geometry>
      <material name="panda_white" />
    </visual>
    <collision>
      <geometry>
        <mesh filename="hd_meshes/collision/hand.vhacd.00.obj" />
      </geometry>
      <material name="panda_white" />
    </collision>
  <collision>
      <geometry>
        <mesh filename="hd_meshes/collision/hand.vhacd.01.obj" />
      </geometry>
      <material name="panda_white" />
    </collision>
  <collision>
      <geometry>
        <mesh filename="hd_meshes/collision/hand.vhacd.02.obj" />
      </geometry>
      <material name="panda_white" />
    </collision>
  <collision>
      <geometry>
        <mesh filename="hd_meshes/collision/hand.vhacd.03.obj" />
      </geometry>
      <material name="panda_white" />
    </collision>
  <collision>
      <geometry>
        <mesh filename="hd_meshes/collision/hand.vhacd.04.obj" />
      </geometry>
      <material name="panda_white" />
    </collision>
  <collision>
      <geometry>
        <mesh filename="hd_meshes/collision/hand.vhacd.05.obj" />
      </geometry>
      <material name="panda_white" />
    </collision>
  <collision>
      <geometry>
        <mesh filename="hd_meshes/collision/hand.vhacd.06.obj" />
      </geometry>
      <material name="panda_white" />
    </collision>
  <collision>
      <geometry>
        <mesh filename="hd_meshes/collision/hand.vhacd.07.obj" />
      </geometry>
      <material name="panda_white" />
    </collision>
  <collision>
      <geometry>
        <mesh filename="hd_meshes/collision/hand.vhacd.08.obj" />
      </geometry>
      <material name="panda_white" />
    </collision>
  <collision>
      <geometry>
        <mesh filename="hd_meshes/collision/hand.vhacd.09.obj" />
      </geometry>
      <material name="panda_white" />
    </collision>
  <collision>
      <geometry>
        <mesh filename="hd_meshes/collision/hand.vhacd.10.obj" />
      </geometry>
      <material name="panda_white" />
    </collision>
  <collision>
      <geometry>
        <mesh filename="hd_meshes/collision/hand.vhacd.11.obj" />
      </geometry>
      <material name="panda_white" />
    </collision>
  <collision>
      <geometry>
        <mesh filename="hd_meshes/collision/hand.vhacd.12.obj" />
      </geometry>
      <material name="panda_white" />
    </collision>
  <collision>
      <geometry>
        <mesh filename="hd_meshes/collision/hand.vhacd.13.obj" />
      </geometry>
      <material name="panda_white" />
    </collision>
  <collision>
      <geometry>
        <mesh filename="hd_meshes/collision/hand.vhacd.14.obj" />
      </geometry>
      <material name="panda_white" />
    </collision>
  <collision>
      <geometry>
        <mesh filename="hd_meshes/collision/hand.vhacd.15.obj" />
      </geometry>
      <material name="panda_white" />
    </collision>
  <collision>
      <geometry>
        <mesh filename="hd_meshes/collision/hand.vhacd.16.obj" />
      </geometry>
      <material name="panda_white" />
    </collision>
  <collision>
      <geometry>
        <mesh filename="hd_meshes/collision/hand.vhacd.17.obj" />
      </geometry>
      <material name="panda_white" />
    </collision>
  <collision>
      <geometry>
        <mesh filename="hd_meshes/collision/hand.vhacd.18.obj" />
      </geometry>
      <material name="panda_white" />
    </collision>
  <collision>
      <geometry>
        <mesh filename="hd_meshes/collision/hand.vhacd.19.obj" />
      </geometry>
      <material name="panda_white" />
    </collision>
  <collision>
      <geometry>
        <mesh filename="hd_meshes/collision/hand.vhacd.20.obj" />
      </geometry>
      <material name="panda_white" />
    </collision>
  <collision>
      <geometry>
        <mesh filename="hd_meshes/collision/hand.vhacd.21.obj" />
      </geometry>
      <material name="panda_white" />
    </collision>
  <collision>
      <geometry>
        <mesh filename="hd_meshes/collision/hand.vhacd.22.obj" />
      </geometry>
      <material name="panda_white" />
    </collision>
  <collision>
      <geometry>
        <mesh filename="hd_meshes/collision/hand.vhacd.23.obj" />
      </geometry>
      <material name="panda_white" />
    </collision>
  <collision>
      <geometry>
        <mesh filename="hd_meshes/collision/hand.vhacd.24.obj" />
      </geometry>
      <material name="panda_white" />
    </collision>
  <collision>
      <geometry>
        <mesh filename="hd_meshes/collision/hand.vhacd.25.obj" />
      </geometry>
      <material name="panda_white" />
    </collision>
  <collision>
      <geometry>
        <mesh filename="hd_meshes/collision/hand.vhacd.26.obj" />
      </geometry>
      <material name="panda_white" />
    </collision>
  <collision>
      <geometry>
        <mesh filename="hd_meshes/collision/hand.vhacd.27.obj" />
      </geometry>
      <material name="panda_white" />
    </collision>
  <collision>
      <geometry>
        <mesh filename="hd_meshes/collision/hand.vhacd.28.obj" />
      </geometry>
      <material name="panda_white" />
    </collision>
  <collision>
      <geometry>
        <mesh filename="hd_meshes/collision/hand.vhacd.29.obj" />
      </geometry>
      <material name="panda_white" />
    </collision>
  <collision>
      <geometry>
        <mesh filename="hd_meshes/collision/hand.vhacd.30.obj" />
      </geometry>
      <material name="panda_white" />
    </collision>
  <collision>
      <geometry>
        <mesh filename="hd_meshes/collision/hand.vhacd.31.obj" />
      </geometry>
      <material name="panda_white" />
    </collision>
  <collision>
      <geometry>
        <mesh filename="hd_meshes/collision/hand.vhacd.32.obj" />
      </geometry>
      <material name="panda_white" />
    </collision>
  <collision>
      <geometry>
        <mesh filename="hd_meshes/collision/hand.vhacd.33.obj" />
      </geometry>
      <material name="panda_white" />
    </collision>
  <collision>
      <geometry>
        <mesh filename="hd_meshes/collision/hand.vhacd.34.obj" />
      </geometry>
      <material name="panda_white" />
    </collision>
  <collision>
      <geometry>
        <mesh filename="hd_meshes/collision/hand.vhacd.35.obj" />
      </geometry>
      <material name="panda_white" />
    </collision>
  <collision>
      <geometry>
        <mesh filename="hd_meshes/collision/hand.vhacd.36.obj" />
      </geometry>
      <material name="panda_white" />
    </collision>
  <collision>
      <geometry>
        <mesh filename="hd_meshes/collision/hand.vhacd.37.obj" />
      </geometry>
      <material name="panda_white" />
    </collision>
  <collision>
      <geometry>
        <mesh filename="hd_meshes/collision/hand.vhacd.38.obj" />
      </geometry>
      <material name="panda_white" />
    </collision>
  <collision>
      <geometry>
        <mesh filename="hd_meshes/collision/hand.vhacd.39.obj" />
      </geometry>
      <material name="panda_white" />
    </collision>
  <collision>
      <geometry>
        <mesh filename="hd_meshes/collision/hand.vhacd.40.obj" />
      </geometry>
      <material name="panda_white" />
    </collision>
  <collision>
      <geometry>
        <mesh filename="hd_meshes/collision/hand.vhacd.41.obj" />
      </geometry>
      <material name="panda_white" />
    </collision>
  <collision>
      <geometry>
        <mesh filename="hd_meshes/collision/hand.vhacd.42.obj" />
      </geometry>
      <material name="panda_white" />
    </collision>
  <collision>
      <geometry>
        <mesh filename="hd_meshes/collision/hand.vhacd.43.obj" />
      </geometry>
      <material name="panda_white" />
    </collision>
  <collision>
      <geometry>
        <mesh filename="hd_meshes/collision/hand.vhacd.44.obj" />
      </geometry>
      <material name="panda_white" />
    </collision>
  <collision>
      <geometry>
        <mesh filename="hd_meshes/collision/hand.vhacd.45.obj" />
      </geometry>
      <material name="panda_white" />
    </collision>
  <collision>
      <geometry>
        <mesh filename="hd_meshes/collision/hand.vhacd.46.obj" />
      </geometry>
      <material name="panda_white" />
    </collision>
  <collision>
      <geometry>
        <mesh filename="hd_meshes/collision/hand.vhacd.47.obj" />
      </geometry>
      <material name="panda_white" />
    </collision>
  <collision>
      <geometry>
        <mesh filename="hd_meshes/collision/hand.vhacd.48.obj" />
      </geometry>
      <material name="panda_white" />
    </collision>
  <collision>
      <geometry>
        <mesh filename="hd_meshes/collision/hand.vhacd.49.obj" />
      </geometry>
      <material name="panda_white" />
    </collision>
  <collision>
      <geometry>
        <mesh filename="hd_meshes/collision/hand.vhacd.50.obj" />
      </geometry>
      <material name="panda_white" />
    </collision>
  <collision>
      <geometry>
        <mesh filename="hd_meshes/collision/hand.vhacd.51.obj" />
      </geometry>
      <material name="panda_white" />
    </collision>
  <collision>
      <geometry>
        <mesh filename="hd_meshes/collision/hand.vhacd.52.obj" />
      </geometry>
      <material name="panda_white" />
    </collision>
  <collision>
      <geometry>
        <mesh filename="hd_meshes/collision/hand.vhacd.53.obj" />
      </geometry>
      <material name="panda_white" />
    </collision>
  <collision>
      <geometry>
        <mesh filename="hd_meshes/collision/hand.vhacd.54.obj" />
      </geometry>
      <material name="panda_white" />
    </collision>
  <collision>
      <geometry>
        <mesh filename="hd_meshes/collision/hand.vhacd.55.obj" />
      </geometry>
      <material name="panda_white" />
    </collision>
  <collision>
      <geometry>
        <mesh filename="hd_meshes/collision/hand.vhacd.56.obj" />
      </geometry>
      <material name="panda_white" />
    </collision>
  <collision>
      <geometry>
        <mesh filename="hd_meshes/collision/hand.vhacd.57.obj" />
      </geometry>
      <material name="panda_white" />
    </collision>
  <collision>
      <geometry>
        <mesh filename="hd_meshes/collision/hand.vhacd.58.obj" />
      </geometry>
      <material name="panda_white" />
    </collision>
  <collision>
      <geometry>
        <mesh filename="hd_meshes/collision/hand.vhacd.59.obj" />
      </geometry>
      <material name="panda_white" />
    </collision>
  <collision>
      <geometry>
        <mesh filename="hd_meshes/collision/hand.vhacd.60.obj" />
      </geometry>
      <material name="panda_white" />
    </collision>
  <collision>
      <geometry>
        <mesh filename="hd_meshes/collision/hand.vhacd.61.obj" />
      </geometry>
      <material name="panda_white" />
    </collision>
  <collision>
      <geometry>
        <mesh filename="hd_meshes/collision/hand.vhacd.62.obj" />
      </geometry>
      <material name="panda_white" />
    </collision>
  <collision>
      <geometry>
        <mesh filename="hd_meshes/collision/hand.vhacd.63.obj" />
      </geometry>
      <material name="panda_white" />
    </collision>
  <collision>
      <geometry>
        <mesh filename="hd_meshes/collision/hand.vhacd.64.obj" />
      </geometry>
      <material name="panda_white" />
    </collision>
  <collision>
      <geometry>
        <mesh filename="hd_meshes/collision/hand.vhacd.65.obj" />
      </geometry>
      <material name="panda_white" />
    </collision>
  <collision>
      <geometry>
        <mesh filename="hd_meshes/collision/hand.vhacd.66.obj" />
      </geometry>
      <material name="panda_white" />
    </collision>
  <collision>
      <geometry>
        <mesh filename="hd_meshes/collision/hand.vhacd.67.obj" />
      </geometry>
      <material name="panda_white" />
    </collision>
  <collision>
      <geometry>
        <mesh filename="hd_meshes/collision/hand.vhacd.68.obj" />
      </geometry>
      <material name="panda_white" />
    </collision>
  <collision>
      <geometry>
        <mesh filename="hd_meshes/collision/hand.vhacd.69.obj" />
      </geometry>
      <material name="panda_white" />
    </collision>
  <collision>
      <geometry>
        <mesh filename="hd_meshes/collision/hand.vhacd.70.obj" />
      </geometry>
      <material name="panda_white" />
    </collision>
  <collision>
      <geometry>
        <mesh filename="hd_meshes/collision/hand.vhacd.71.obj" />
      </geometry>
      <material name="panda_white" />
    </collision>
  <collision>
      <geometry>
        <mesh filename="hd_meshes/collision/hand.vhacd.72.obj" />
      </geometry>
      <material name="panda_white" />
    </collision>
  <collision>
      <geometry>
        <mesh filename="hd_meshes/collision/hand.vhacd.73.obj" />
      </geometry>
      <material name="panda_white" />
    </collision>
  <collision>
      <geometry>
        <mesh filename="hd_meshes/collision/hand.vhacd.74.obj" />
      </geometry>
      <material name="panda_white" />
    </collision>
  <collision>
      <geometry>
        <mesh filename="hd_meshes/collision/hand.vhacd.75.obj" />
      </geometry>
      <material name="panda_white" />
    </collision>
  <collision>
      <geometry>
        <mesh filename="hd_meshes/collision/hand.vhacd.76.obj" />
      </geometry>
      <material name="panda_white" />
    </collision>
  <collision>
      <geometry>
        <mesh filename="hd_meshes/collision/hand.vhacd.77.obj" />
      </geometry>
      <material name="panda_white" />
    </collision>
  <collision>
      <geometry>
        <mesh filename="hd_meshes/collision/hand.vhacd.78.obj" />
      </geometry>
      <material name="panda_white" />
    </collision>
  <collision>
      <geometry>
        <mesh filename="hd_meshes/collision/hand.vhacd.79.obj" />
      </geometry>
      <material name="panda_white" />
    </collision>
  <collision>
      <geometry>
        <mesh filename="hd_meshes/collision/hand.vhacd.80.obj" />
      </geometry>
      <material name="panda_white" />
    </collision>
  <collision>
      <geometry>
        <mesh filename="hd_meshes/collision/hand.vhacd.81.obj" />
      </geometry>
      <material name="panda_white" />
    </collision>
  <collision>
      <geometry>
        <mesh filename="hd_meshes/collision/hand.vhacd.82.obj" />
      </geometry>
      <material name="panda_white" />
    </collision>
  <collision>
      <geometry>
        <mesh filename="hd_meshes/collision/hand.vhacd.83.obj" />
      </geometry>
      <material name="panda_white" />
    </collision>
  <collision>
      <geometry>
        <mesh filename="hd_meshes/collision/hand.vhacd.84.obj" />
      </geometry>
      <material name="panda_white" />
    </collision>
  <collision>
      <geometry>
        <mesh filename="hd_meshes/collision/hand.vhacd.85.obj" />
      </geometry>
      <material name="panda_white" />
    </collision>
  <collision>
      <geometry>
        <mesh filename="hd_meshes/collision/hand.vhacd.86.obj" />
      </geometry>
      <material name="panda_white" />
    </collision>
  <collision>
      <geometry>
        <mesh filename="hd_meshes/collision/hand.vhacd.87.obj" />
      </geometry>
      <material name="panda_white" />
    </collision>
  <collision>
      <geometry>
        <mesh filename="hd_meshes/collision/hand.vhacd.88.obj" />
      </geometry>
      <material name="panda_white" />
    </collision>
  <collision>
      <geometry>
        <mesh filename="hd_meshes/collision/hand.vhacd.89.obj" />
      </geometry>
      <material name="panda_white" />
    </collision>
  <collision>
      <geometry>
        <mesh filename="hd_meshes/collision/hand.vhacd.90.obj" />
      </geometry>
      <material name="panda_white" />
    </collision>
  <collision>
      <geometry>
        <mesh filename="hd_meshes/collision/hand.vhacd.91.obj" />
      </geometry>
      <material name="panda_white" />
    </collision>
  <collision>
      <geometry>
        <mesh filename="hd_meshes/collision/hand.vhacd.92.obj" />
      </geometry>
      <material name="panda_white" />
    </collision>
  <collision>
      <geometry>
        <mesh filename="hd_meshes/collision/hand.vhacd.93.obj" />
      </geometry>
      <material name="panda_white" />
    </collision>
  <collision>
      <geometry>
        <mesh filename="hd_meshes/collision/hand.vhacd.94.obj" />
      </geometry>
      <material name="panda_white" />
    </collision>
  <collision>
      <geometry>
        <mesh filename="hd_meshes/collision/hand.vhacd.95.obj" />
      </geometry>
      <material name="panda_white" />
    </collision>
  <collision>
      <geometry>
        <mesh filename="hd_meshes/collision/hand.vhacd.96.obj" />
      </geometry>
      <material name="panda_white" />
    </collision>
  <collision>
      <geometry>
        <mesh filename="hd_meshes/collision/hand.vhacd.97.obj" />
      </geometry>
      <material name="panda_white" />
    </collision>
  <collision>
      <geometry>
        <mesh filename="hd_meshes/collision/hand.vhacd.98.obj" />
      </geometry>
      <material name="panda_white" />
    </collision>
  <collision>
      <geometry>
        <mesh filename="hd_meshes/collision/hand.vhacd.99.obj" />
      </geometry>
      <material name="panda_white" />
    </collision>
  <collision>
      <geometry>
        <mesh filename="hd_meshes/collision/hand.vhacd.100.obj" />
      </geometry>
      <material name="panda_white" />
    </collision>
  <collision>
      <geometry>
        <mesh filename="hd_meshes/collision/hand.vhacd.101.obj" />
      </geometry>
      <material name="panda_white" />
    </collision>
  <collision>
      <geometry>
        <mesh filename="hd_meshes/collision/hand.vhacd.102.obj" />
      </geometry>
      <material name="panda_white" />
    </collision>
  <collision>
      <geometry>
        <mesh filename="hd_meshes/collision/hand.vhacd.103.obj" />
      </geometry>
      <material name="panda_white" />
    </collision>
  <collision>
      <geometry>
        <mesh filename="hd_meshes/collision/hand.vhacd.104.obj" />
      </geometry>
      <material name="panda_white" />
    </collision>
  <collision>
      <geometry>
        <mesh filename="hd_meshes/collision/hand.vhacd.105.obj" />
      </geometry>
      <material name="panda_white" />
    </collision>
  <collision>
      <geometry>
        <mesh filename="hd_meshes/collision/hand.vhacd.106.obj" />
      </geometry>
      <material name="panda_white" />
    </collision>
  <collision>
      <geometry>
        <mesh filename="hd_meshes/collision/hand.vhacd.107.obj" />
      </geometry>
      <material name="panda_white" />
    </collision>
  </link>
  <link name="panda_leftfinger">
       <contact>
      <friction_anchor />
      <stiffness value="30000.0" />
      <damping value="1000.0" />
      <spinning_friction value="0.1" />
      <lateral_friction value="1.0" />
    </contact>
  	<inertial>
      <origin rpy="0 0 0" xyz="0 0.01 0.02" />
       <mass value="0.1" />
       <inertia ixx="0.1" ixy="0" ixz="0" iyy="0.1" iyz="0" izz="0.1" />
    </inertial>
    <visual>
      <geometry>
        <mesh filename="hd_meshes/visual/finger.dae" />
      </geometry>
      <material name="panda_white" />
    </visual>
    <collision>
      <geometry>
        <mesh filename="hd_meshes/collision/finger.vhacd.00.obj" />
      </geometry>
      <material name="panda_white" />
    </collision>
  <collision>
      <geometry>
        <mesh filename="hd_meshes/collision/finger.vhacd.01.obj" />
      </geometry>
      <material name="panda_white" />
    </collision>
  <collision>
      <geometry>
        <mesh filename="hd_meshes/collision/finger.vhacd.02.obj" />
      </geometry>
      <material name="panda_white" />
    </collision>
  <collision>
      <geometry>
        <mesh filename="hd_meshes/collision/finger.vhacd.03.obj" />
      </geometry>
      <material name="panda_white" />
    </collision>
  </link>
  <link name="panda_rightfinger">
        <contact>
      <friction_anchor />
      <stiffness value="30000.0" />
      <damping value="1000.0" />
      <spinning_friction value="0.1" />
      <lateral_friction value="1.0" />
    </contact>

  	<inertial>
      <origin rpy="0 0 0" xyz="0 -0.01 0.02" />
       <mass value="0.1" />
       <inertia ixx="0.1" ixy="0" ixz="0" iyy="0.1" iyz="0" izz="0.1" />
    </inertial>
    <visual>
      <origin rpy="0 0 3.14159265359" xyz="0 0 0" />
      <geometry>
        <mesh filename="hd_meshes/visual/finger.dae" />
      </geometry>
      <material name="panda_white" />
    </visual>
    <collision>
      <origin rpy="0 0 3.14159265359" xyz="0 0 0" />
      <geometry>
        <mesh filename="hd_meshes/collision/finger.vhacd.00.obj" />
      </geometry>
      <material name="panda_white" />
    </collision>
  <collision>
      <origin rpy="0 0 3.14159265359" xyz="0 0 0" />
      <geometry>
        <mesh filename="hd_meshes/collision/finger.vhacd.01.obj" />
      </geometry>
      <material name="panda_white" />
    </collision>
  <collision>
      <origin rpy="0 0 3.14159265359" xyz="0 0 0" />
      <geometry>
        <mesh filename="hd_meshes/collision/finger.vhacd.02.obj" />
      </geometry>
      <material name="panda_white" />
    </collision>
  <collision>
      <origin rpy="0 0 3.14159265359" xyz="0 0 0" />
      <geometry>
        <mesh filename="hd_meshes/collision/finger.vhacd.03.obj" />
      </geometry>
      <material name="panda_white" />
    </collision>
  </link>
  <joint name="panda_finger_joint1" type="prismatic">
    <parent link="panda_hand" />
    <child link="panda_leftfinger" />
    <origin rpy="0 0 0" xyz="0 0 0.0584" />
    <axis xyz="0 1 0" />
    <limit effort="20" lower="0.0" upper="0.04" velocity="0.2" />
  </joint>
  <joint name="panda_finger_joint2" type="prismatic">
    <parent link="panda_hand" />
    <child link="panda_rightfinger" />
    <origin rpy="0 0 0" xyz="0 0 0.0584" />
    <axis xyz="0 -1 0" />
    <limit effort="20" lower="0.0" upper="0.04" velocity="0.2" />
    <mimic joint="panda_finger_joint1" />
  </joint>
  <link name="right_gripper">
    <inertial>

      <mass value="0.01" />
      <inertia ixx="0.0001" ixy="0.0" ixz="0.0" iyy="0.0001" iyz="0.0" izz="0.0001" />
      <origin rpy="0 0 0" xyz="0 0 0" />
    </inertial>
  </link>
  <joint name="right_gripper" type="fixed">
    <origin rpy="0 0 2.35619449019" xyz="0 0 0.1" />
      <axis xyz="0 0 1" />
    <parent link="panda_link8" />
    <child link="right_gripper" />
  </joint>
   <link name="panda_grasptarget">
 <inertial>
      <origin rpy="0 0 0" xyz="0 0 0" />
       <mass value="0.0" />
       <inertia ixx="0.1" ixy="0" ixz="0" iyy="0.1" iyz="0" izz="0.1" />
    </inertial>
   </link>
   <joint name="panda_grasptarget_hand" type="fixed">
    <parent link="panda_hand" />
    <child link="panda_grasptarget" />
    <origin rpy="0 0 0" xyz="0 0 0.105" />
  </joint>

</robot>
